Workbook
Name valuevx: 42.314159
Name vertex42_copyright: "© 2019 Vertex42 LLC"
Name vertex42_id: "project-budget-detailed.xlsx"
Name vertex42_title: "Project Budget Template"

Sheet Pay dates
B1: Direct debt Dates
B3: Expenses | C3: Day
B4: Mortgage or rent | C4: 1
B5: Council Tax | C5: 10
B6: Phone Fab and Martina | C6: 22
B7: Electricity + Gas | C7: 23
B8: Ageas | C8: 17
B9: Water | C9: 22
B10: TV Licence | C10: 22
B11: Internet (Talk Talk) | C11: 21
B12: Adobe | C12: 15
B13: Amazon prime+Kindle | C13: 8
B14: WW | C14: 13
B15: Aviva | C15: 1
... B17: DVLA 1 | C17: 1

Sheet Summary
B2: 2026 Summary
B4: Totals | I4: Total fixed expenses | L4: Savings | Q4: Month | R4: Savings | S4: Overpayments | T4: % Total
B5: Month | C5: In | D5: Out | E5: Balance | F5: Savings | G5: Overpayments | I5: Mortgage (M) | J5: ='Jan-26'!C12+'Feb-26'!C12 -> 1416.1 | L5: Emergency | M5: Matteo | N5: Lucas | O5: Other | Q5: Jan | R5: =(F6/C6)*1 -> 0.76952464 | S5: =(G6/C6)*1 -> 0.010106563 | T5: =SUM(R5:S5) -> 0.77963121
B6: Jan | C6: ='Jan-26'!C9 -> 23845.89 | D6: ='Jan-26'!F5+'Jan-26'!F6+'Jan-26'!F7 -> 23845.89 | E6: =((C6-D6))+'Jan-26'!$J$18+'Jan-26'!$J$19 -> 18591 | F6: ='Jan-26'!$J$18 -> 18350 | G6: ='Jan-26'!$J$19 -> 241 | I6: Aviva (J) | J6: ='Jan-26'!C13+'Feb-26'!C13 -> 30.2 | L6: ='Jan-26'!$J$5 -> 14593.73 | M6: ='Jan-26'!$J$6 -> 10023.96 | N6: ='Jan-26'!$J$7 -> 4868.99 | O6: ='Jan-26'!$J$8 -> 0 | Q6: Feb
B7: Feb | C7: ='Feb-26'!C9 -> 5623.07 | D7: ='Feb-26'!F5+'Feb-26'!F6+'Feb-26'!F7 -> 5623.07 | E7: =((C7-D7))+'Feb-26'!$J$18+'Feb-26'!$J$19 -> 291 | F7: ='Feb-26'!$J$18 -> 50 | G7: ='Feb-26'!$J$19 -> 241 | I7: DVLA (J) | J7: ='Jan-26'!C14+'Feb-26'!C14 -> 34.12 | L7: ='Feb-26'!$J$5 -> 32577.82 | M7: ='Feb-26'!$J$6 -> 10046.66 | N7: ='Feb-26'!$J$7 -> 5018.53 | O7: ='Jan-26'!$J$8 -> 0 | Q7: Mar
B8: Mar | I8: Electricity + Gas(Bulb) (J) | J8: ='Jan-26'!C15+'Feb-26'!C15 -> 230.66 | Q8: Apr
B9: Apr | I9: Council Tax (J) | J9: ='Jan-26'!C16+'Feb-26'!C16 -> 168 | Q9: May
B10: May | I10: Ageas (M) | J10: ='Jan-26'!C17+'Feb-26'!C17 -> 43.88 | Q10: Jun
B11: Jun | I11: Water (J) | J11: ='Jan-26'!C18+'Feb-26'!C18 -> 132 | Q11: Jul
B12: Jul | I12: Phones (three) (F) | J12: ='Jan-26'!C19+'Feb-26'!C19 -> 89.96 | Q12: Aug
B13: Aug | Q13: Sep
B14: Sep | Q14: Oct
B15: Oct | Q15: Nov
B16: Nov | Q16: Dec
B17: Dec
B19: Total | C19: =SUM(C6:C17) -> 29468.96 | D19: =SUM(D6:D17) -> 29468.96 | E19: =SUM(E6:E17) -> 18882 | F19: =SUM(F6:F17) -> 18400 | G19: =SUM(G6:G17) -> 482 | I19: Total | J19: =SUM(J5:J17) -> 2144.92 | L19: Total in Savings: | N19: =SUM(L7:O7) -> 47643.01
C21: Goals | E21: Actual | F21: % | I21: Total extra expenses | L21: Total Interest: | N21: ='Jan-26'!M9+'Feb-26'!M9 -> 181.71
B22: . | C22: Savings | D22: 15000 | E22: =F19-16850 -> 1550 | F22: =E22/D22*1 -> 0.10333333 | I22: Groceries | J22: ='Jan-26'!J12+'Feb-26'!J12 -> 947 | L22: AVG Interest p/ month: | N22: =N21/2 -> 90.855
C23: Overpayments | D23: =708.05*4 -> 2832.2 | E23: =G19 -> 482 | F23: =E23/D23*1 -> 0.17018572 | I23: Leisure / Include day outs | J23: ='Jan-26'!J13+'Feb-26'!J13 -> 502.87
C24: Interest | D24: 1100 | E24: =N21 -> 181.71 | F24: =E24/D24*1 -> 0.16519091 | I24: Others (Not essential) | J24: ='Jan-26'!J14+'Feb-26'!J14 -> 4888.61 | M24: Other's
I25: Others (Essential) | J25: ='Jan-26'!J15+'Feb-26'!J15 -> 786.72 | L25: Gifts from Italy | N25: =12937+513.61 -> 13450.61
I26: Holidays | J26: ='Jan-26'!J16+'Feb-26'!J16 -> 956.97 | L26: Divident MRL | N26: 5000
I27: Clothing | J27: ='Jan-26'!J17+'Feb-26'!J17 -> 355.12 | N27: =SUM(N25:O26) -> 18450.61 | Q27: extra
I28: Savings | J28: ='Jan-26'!J18+'Feb-26'!J18 -> 18400
I29: Overpayments | J29: ='Jan-26'!J19+'Feb-26'!J19 -> 482
I31: SubTotal | J31: =SUM(J22:J29)-J28-J29 -> 8437.29
C66: `

Sheet Mar-26
B2: February
B4: Income | E4: Expenses | F4: Total | G4: % of income | I4: Savings | L4: Interest | N4: Diff
B5: Fabricio Rocha | C5: =3396.69-60 -> 3336.69 | E5: Total Fixed expenses | F5: =SUM(C12:C21) -> 975.48 | G5: =(F5/C9)*1 -> 0.18780901 | I5: Emergency | J5: 32639.79 | L5: 0.0356 | M5: 61.97 | N5: 0
B6: Martina Sanna | C6: 1684.11 | E6: Total Other expenses | F6: =SUM(F12:F200) -> 600.49 | G6: =(F6/C9)*1 -> 0.11561224 | I6: Matteo | J6: 10065.77 | L6: 0.0356 | M6: 19.11 | N6: 0
B7: Child Benefits | C7: =173.2 -> 173.2 | E7: "One off" big expenses | F7: =SUM(J22:J24) -> 0 | G7: =(F7/C9)*1 -> 0 | I7: Lucas | J7: 5034.38 | L7: 0.0512 | M7: 15.85 | N7: 0
B8: Other's | C8: 0 | E8: Balance | F8: =(C9-(F5+F6)) -> 3618.03 | G8: As of today | I8: Tradind 212 | J8: 300 | L8: 0.0433 | M8: 0.55 | N8: 0
B9: Total Income | C9: =SUM(C5:C8) -> 5194 | E9: Discrepancy | F9: =G9-F8 -> 204.87 | G9: =89.65+0.01+3983.61-C19-C18-C17-C15-C13 -> 3822.9 | I9: Balance | J9: =SUM(J5:J8) -> 48039.94 | L9: Total | M9: =SUM(M5:M8) -> 97.48 | N9: =SUM(N5:N8) -> 0
B11: Monthly expenses | C11: Cost | D11: D | E11: Other expenses | F11: Cost | G11: Type | I11: Total extra expenses | L11: Lucas - Rainy Day Saver (Barclays
A12: 1 | B12: Mortgage (M) | C12: 708.05 | D12: 2 | E12: Rocksteady | F12: 44.68 | G12: Others (Not essential) | I12: Groceries | J12: =SUMIF(G:G, "Groceries", F:F) -> 0 | L12: Balance and over | M12: Gross pa % | N12: AER %
A13: 3 | B13: Aviva (J) | C13: 15.1 | D13: 2 | E13: Swimming | F13: 31.5 | G13: Others (Not essential) | I13: Leisure / Days out | J13: =SUMIF(G:G, "Leisure / Days out", F:F) -> 0 | L13: £5,001 and over | M13: 1.16 | N13: 1.16
A14: 3 | B14: DVLA (J) | C14: 17.06 | D14: 2 | E14: Parent pay | F14: 2 | G14: Others (Not essential) | I14: Others (Not essential) | J14: =SUMIF(G:G, "Others (Not essential)", F:F) -> 240.28 | L14: £1 - £5,000 | M14: 5 | N14: 5.12
A15: 7 | B15: Electricity + Gas(Bulb) (J) | C15: 115.33 | D15: 2 | E15: Parent pay | F15: 2 | G15: Others (Not essential) | I15: Others (Essential) | J15: =SUMIF(G:G, "Others (Essential)", F:F) -> 0
A16: 11 | B16: Council Tax (J) | C16: 0 | D16: 2 | E16: Sprive | F16: 28 | G16: Others (Not essential) | I16: Holidays | J16: =SUMIF(G:G, "Holidays", F:F) -> 0 | L16: Emergency - Blue Rewards Saver
A17: 17 | B17: Ageas (M) | C17: 21.94 | D17: 2 | E17: Greggs | F17: 3.55 | G17: Others (Not essential) | I17: Clothing | J17: =SUMIF(G:G, "Clothing", F:F) -> 0 | L17: Balance and over | M17: Gross pa % | N17: AER %
A18: 22 | B18: Water (J) | C18: 66 | D18: 2 | E18: Barber | F18: 24 | G18: Others (Not essential) | I18: Savings | J18: =SUMIF(G:G, "Savings", F:F) -> 360.21 | L18: £1 and over | M18: 3.5 | N18: 3.56
A19: 24 | B19: Phones (three) (F) | C19: 32 | D19: 2 | E19: Temu Simo gift | F19: 34.41 | G19: Others (Not essential) | I19: Overpayment | J19: =SUMIF(G:G, "Overpayment", F:F) -> 0 | L19: Lower rate | M19: 1.15 | N19: 1.16
D20: 1 | E20: PureGym | F20: 34.99 | G20: Others (Not essential)
D21: 1 | E21: Amazon | F21: 35.15 | G21: Others (Not essential) | I21: Others big one off expenses | L21: Matteo - Blue Rewards Saver
D22: 2 | E22: House | F22: 360.21 | G22: Savings | L22: Balance and over | M22: Gross pa % | N22: AER %
L23: £1 and over | M23: 3.5 | N23: 3.56
C24: Start of the month | L24: Lower rate | M24: 1.15 | N24: 1.16
B25: M | C25: 1500
B26: F | C26: 1500 | I26: Money taken from savings | L26: Other - Trading 212
B27: J | C27: 848 | L27: 0.0433

Sheet Feb-26
B2: February
B4: Income | E4: Expenses | F4: Total | G4: % of income | I4: Savings | L4: Interest | N4: Diff
B5: Fabricio Rocha | C5: =3396.69-420 -> 2976.69 | E5: Total Fixed expenses | F5: =SUM(C12:C21) -> 988.46 | G5: =(F5/C9)*1 -> 0.17578654 | I5: Emergency | J5: 32577.82 | L5: 0.0356 | M5: 66.09 | N5: 0
B6: Martina Sanna | C6: 1650.31 | E6: Total Other expenses | F6: =SUM(F12:F200) -> 4634.61 | G6: =(F6/C9)*1 -> 0.82421346 | I6: Matteo | J6: 10046.66 | L6: 0.0356 | M6: 17.54 | N6: 0
B7: Child Benefits | C7: =173.2*2 -> 346.4 | E7: "One off" big expenses | F7: =SUM(J22:J24) -> 0 | G7: =(F7/C9)*1 -> 0 | I7: Lucas | J7: 5018.53 | L7: 0.0512 | M7: 22.7 | N7: 0
B8: Other's | C8: =513.61+86.06+50 -> 649.67 | E8: Balance | F8: =(C9-(F5+F6)) -> 9.094947e-13 | G8: As of today | I8: Tradind 212 | J8: 300 | L8: 0.0433 | M8: 0.55 | N8: 0
B9: Total Income | C9: =SUM(C5:C8) -> 5623.07 | E9: Discrepancy | I9: Balance | J9: =SUM(J5:J8) -> 47943.01 | L9: Total | M9: =SUM(M5:M8) -> 106.88 | N9: =SUM(N5:N8) -> 0
B11: Monthly expenses | C11: Cost | D11: D | E11: Other expenses | F11: Cost | G11: Type | I11: Total extra expenses | L11: Lucas - Rainy Day Saver (Barclays
A12: 1 | B12: Mortgage (M) | C12: 708.05 | D12: 2 | E12: Kids about Tarn | F12: 50 | G12: Others (Not essential) | I12: Groceries | J12: =SUMIF(G:G, "Groceries", F:F) -> 386.86 | L12: Balance and over | M12: Gross pa % | N12: AER %
A13: 3 | B13: Aviva (J) | C13: 15.1 | D13: 2 | E13: Parking fine | F13: 35 | G13: Others (Not essential) | I13: Leisure / Days out | J13: =SUMIF(G:G, "Leisure / Days out", F:F) -> 383.53 | L13: £5,001 and over | M13: 1.16 | N13: 1.16
A14: 3 | B14: DVLA (J) | C14: 17.06 | D14: 1 | E14: Rocksteady | F14: 44.68 | G14: Others (Not essential) | I14: Others (Not essential) | J14: =SUMIF(G:G, "Others (Not essential)", F:F) -> 3081.22 | L14: £1 - £5,000 | M14: 5 | N14: 5.12
A15: 7 | B15: Electricity + Gas(Bulb) (J) | C15: 115.33 | D15: 1 | E15: Swimming | F15: 31.5 | G15: Others (Not essential) | I15: Others (Essential) | J15: =SUMIF(G:G, "Others (Essential)", F:F) -> 372.05
A16: 11 | B16: Council Tax (J) | C16: 0 | D16: 1 | E16: Dentist | F16: 70 | G16: Others (Not essential) | I16: Holidays | J16: =SUMIF(G:G, "Holidays", F:F) -> 0 | L16: Emergency - Blue Rewards Saver
A17: 17 | B17: Ageas (M) | C17: 21.94 | D17: 1 | E17: Dentist | F17: 105 | G17: Others (Not essential) | I17: Clothing | J17: =SUMIF(G:G, "Clothing", F:F) -> 119.95 | L17: Balance and over | M17: Gross pa % | N17: AER %
A18: 22 | B18: Water (J) | C18: 66 | D18: 1 | E18: Rain jacket | F18: 56.97 | G18: Clothing | I18: Savings | J18: =SUMIF(G:G, "Savings", F:F) -> 50 | L18: £1 and over | M18: 3.5 | N18: 3.56
A19: 24 | B19: Phones (three) (F) | C19: =22.49+22.49 -> 44.98 | D19: 1 | E19: Carpet materials | F19: 1667 | G19: Others (Not essential) | I19: Overpayment | J19: =SUMIF(G:G, "Overpayment", F:F) -> 241 | L19: Lower rate | M19: 1.15 | N19: 1.16
D20: 4 | E20: Blue rewards | F20: 5 | G20: Others (Not essential)
D21: 4 | E21: AA | F21: 9.18 | G21: Others (Not essential) | I21: Others big one off expenses | L21: Matteo - Blue Rewards Saver
D22: 4 | E22: Ozzies Matteo | F22: 30 | G22: Others (Not essential) | L22: Balance and over | M22: Gross pa % | N22: AER %
D23: 4 | E23: Hotel training run | F23: 79.31 | G23: Leisure / Days out | L23: £1 and over | M23: 3.5 | N23: 3.56
C24: Start of the month | D24: 4 | E24: Blink | F24: 2.5 | G24: Others (Not essential) | L24: Lower rate | M24: 1.15 | N24: 1.16
B25: M | C25: 1500 | D25: 6 | E25: Amazon | F25: 20.47 | G25: Others (Not essential)
B26: F | C26: 1500 | D26: 6 | E26: Saintsburys | F26: 31.54 | G26: Groceries | I26: Money taken from savings | L26: Other - Trading 212
B27: J | C27: 848 | D27: 9 | E27: Ultimate garage | F27: 74.98 | G27: Others (Not essential) | L27: 0.0433
D28: 9 | E28: Bus | F28: 3.3 | G28: Others (Not essential)
D29: 9 | E29: Tv license | F29: 14.95 | G29: Leisure / Days out
D30: 9 | E30: Prime | F30: 8.99 | G30: Leisure / Days out
D31: 9 | E31: Aldi | F31: 84.48 | G31: Groceries
D32: 9 | E32: Card factory | F32: 9.34 | G32: Others (Not essential)
D33: 9 | E33: M&S | F33: 14.65 | G33: Others (Not essential)
D34: 11 | E34: WOW | F34: 9.99 | G34: Leisure / Days out
D35: 13 | E35: Sheilas Wheels Insur. | F35: 276.05 | G35: Others (Essential)
D36: 13 | E36: Amazon | F36: 11.65 | G36: Others (Not essential)
D37: 13 | E37: Amazon | F37: 9.49 | G37: Others (Not essential)
D38: 12 | E38: Sprive | F38: 11.01 | G38: Others (Not essential)
D39: 3 | E39: Blue rewards | F39: 5 | G39: Others (Not essential)
... D97: 28 | E97: Bus | F97: 2.5 | G97: Others (Not essential)
E98: Discrepancy | F98: 64.42 | G98: Others (Not essential)

Sheet Jan-26
B2: January
B4: Income | E4: Expenses | F4: Total | G4: % of income | I4: Savings | L4: Interest | N4: Diff
B5: Fabricio Rocha | C5: 3396.69 | E5: Total Fixed expenses | F5: =SUM(C12:C21) -> 1156.46 | G5: =(F5/C9)*1 -> 0.048497246 | I5: Emergency | J5: 14593.73 | L5: 0.0356 | M5: 31.47 | N5: 0
B6: Martina Sanna | C6: 1650.31 | E6: Total Other expenses | F6: =SUM(F12:F200) -> 22689.43 | G6: =(F6/C9)*1 -> 0.95150275 | I6: Matteo | J6: 10023.96 | L6: 0.0356 | M6: 23.85 | N6: 0
B7: Child Benefits | C7: =173.2 -> 173.2 | E7: "One off" big expenses | F7: =SUM(J22:J24) -> 0 | G7: =(F7/C9)*1 -> 0 | I7: Lucas | J7: 4868.99 | L7: 0.0512 | M7: 18.06 | N7: 0
B8: Other's | C8: =12937+5000+4.75+263.94+420 -> 18625.69 | E8: Balance | F8: =(C9-(F5+F6)) -> -1.0913936e-11 | G8: As of today | I8: Other | J8: 0 | L8: 0.0433 | M8: 1.45 | N8: 0
B9: Total Income | C9: =SUM(C5:C8) -> 23845.89 | E9: Discrepancy | I9: Balance | J9: =SUM(J5:J8) -> 29486.68 | L9: Total | M9: =SUM(M5:M8) -> 74.83 | N9: =SUM(N5:N8) -> 0
B11: Monthly expenses | C11: Cost | D11: D | E11: Other expenses | F11: Cost | G11: Type | I11: Total extra expenses | L11: Lucas - Rainy Day Saver (Barclays
A12: 1 | B12: Mortgage (M) | C12: 708.05 | D12: 1 | E12: Lucas | F12: 132 | G12: Savings | I12: Groceries | J12: =SUMIF(G:G, "Groceries", F:F) -> 560.14 | L12: Balance and over | M12: Gross pa % | N12: AER %
A13: 3 | B13: Aviva (J) | C13: 15.1 | D13: 1 | E13: Emergency | F13: 1068 | G13: Savings | I13: Leisure / Days out | J13: =SUMIF(G:G, "Leisure / Days out", F:F) -> 119.34 | L13: £5,001 and over | M13: 1.16 | N13: 1.16
A14: 3 | B14: DVLA (J) | C14: 17.06 | D14: 2 | E14: Overpayment | F14: 241 | G14: Overpayment | I14: Others (Not essential) | J14: =SUMIF(G:G, "Others (Not essential)", F:F) -> 1807.39 | L14: £1 - £5,000 | M14: 5 | N14: 5.12
A15: 7 | B15: Electricity + Gas(Bulb) (J) | C15: 115.33 | D15: 1 | E15: Barclaycard | F15: 100 | G15: Others (Not essential) | I15: Others (Essential) | J15: =SUMIF(G:G, "Others (Essential)", F:F) -> 414.67
A16: 11 | B16: Council Tax (J) | C16: 168 | D16: 5 | E16: Ozzies Matteo | F16: 25 | G16: Others (Essential) | I16: Holidays | J16: =SUMIF(G:G, "Holidays", F:F) -> 956.97 | L16: Emergency - Blue Rewards Saver
A17: 17 | B17: Ageas (M) | C17: 21.94 | D17: 5 | E17: Amazon | F17: 13.45 | G17: Others (Not essential) | I17: Clothing | J17: =SUMIF(G:G, "Clothing", F:F) -> 235.17 | L17: Balance and over | M17: Gross pa % | N17: AER %
A18: 22 | B18: Water (J) | C18: 66 | D18: 5 | E18: Blue Rewards | F18: 5 | G18: Others (Essential) | I18: Savings | J18: =SUMIF(G:G, "Savings", F:F) -> 18350 | L18: £1 and over | M18: 3.5 | N18: 3.56
A19: 24 | B19: Phones (three) (F) | C19: =22.49+22.49 -> 44.98 | D19: 5 | E19: Blink | F19: 2.5 | G19: Others (Not essential) | I19: Overpayment | J19: =SUMIF(G:G, "Overpayment", F:F) -> 241 | L19: Lower rate | M19: 1.15 | N19: 1.16
D20: 5 | E20: Yeadon Barber | F20: 40 | G20: Others (Essential)
D21: 5 | E21: AA | F21: 9.08 | G21: Others (Essential) | I21: Others big one off expenses | L21: Matteo - Blue Rewards Saver
D22: 6 | E22: Amazon | F22: 11.99 | G22: Others (Not essential) | L22: Balance and over | M22: Gross pa % | N22: AER %
D23: 6 | E23: Sparkling Water - Sprive | F23: 45 | G23: Groceries | L23: £1 and over | M23: 3.5 | N23: 3.56
C24: Start of the month | D24: 6 | E24: Sportsdirect | F24: 60.19 | G24: Clothing | L24: Lower rate | M24: 1.15 | N24: 1.16
B25: M | C25: 1500 | D25: 7 | E25: Asda | F25: 0.97 | G25: Others (Not essential)
B26: F | C26: 1500 | D26: 7 | E26: Amazon | F26: 19.93 | G26: Others (Not essential) | I26: Money taken from savings | L26: Other - Trading 212
B27: J | C27: 848 | D27: 8 | E27: TV license | F27: 14.95 | G27: Leisure / Days out | L27: 0.0433
D28: 8 | E28: Prime | F28: 8.99 | G28: Leisure / Days out
D29: 9 | E29: Amazon | F29: 11.34 | G29: Others (Not essential)
D30: 9 | E30: AMEX TP 260.86 PAID | F30: 260.86 | G30: Others (Not essential)
D31: 12 | E31: LegoLand | F31: 956.97 | G31: Holidays
D32: 12 | E32: Trail Shoes | G32: Clothing | H32: refunded
D33: 12 | E33: Card Factory | F33: 3.87 | G33: Others (Not essential)
D34: 12 | E34: Morrisons | F34: 60.02 | G34: Groceries
D35: 2 | E35: Swimming | F35: 31.5 | G35: Others (Not essential)
D36: 2 | E36: Rocksteady | F36: 44.68 | G36: Others (Not essential)
D37: 2 | E37: Companies House | F37: 50 | G37: Others (Not essential)
D38: 5 | E38: Emergency | F38: 4500 | G38: Savings
D39: 5 | E39: Infinity | F39: 8.15 | G39: Leisure / Days out
D40: 5 | E40: Infinity | F40: 16.44 | G40: Leisure / Days out
D41: 5 | E41: Blue Rewards | F41: 5 | G41: Others (Not essential)
D42: 5 | E42: Gregs | F42: 0.7 | G42: Leisure / Days out
D43: 6 | E43: Rachel | F43: 10 | G43: Others (Not essential)
...

Sheet Next house
B3: Quanto temos hoje (Jan 2026) | E3: Quanto precisamos para uma casa de: | H3: Total | I3: Mortgate | J3: Interest | K3: Term
H4: 450000 | I4: =H4-F5 -> 405000 | J4: 0.0415 | K4: 35
B5: Equity we can take out | C5: 40000 | E5: 10% deposit | F5: =H4*0.1 -> 45000 | I5: Monthly payments | J5: =-PMT(J4/12, K4*12, I4) -> 1829.8578
B6: Savings | C6: 35000 | E6: Stamp duty | F6: =0.05*MIN(H4,125000) + 0.07*MAX(0,MIN(H4-125000,125000)) + 0.1*MAX(0,MIN(H4-250000,675000)) + 0.15*MAX(0,MIN(H4-925000,575000)) + 0.17*MAX(0,H4-1500000) -> 35000
B7: MRL (dividends) | C7: 0 | E7: Solicitor | F7: 2000
B8: Italy (gift) | C8: 10000 | E8: Others (surveys etc) | F8: 1000
E9: Woodlea grove penalty | F9: 2000
B10: Total | C10: =SUM(C5:C8) -> 85000
B12: Difference | C12: =C10-F12 -> 0 | E12: Total | F12: =SUM(F5:F10) -> 85000

Sheet expenses
B2: Woodlea Grove rented | I2: Two houses
B4: Income | E4: Expenses | I4: Income | L4: Expenses
B5: Fabricio Rocha | C5: 3400 | E5: Total Fixed expenses | F5: =SUM(C12:C20) -> 2264 | G5: =(F5/C9)*1 -> 0.4353955 | I5: Fabricio Rocha | J5: 3400 | L5: Total Fixed expenses | M5: =SUM(J12:J20) -> 3227.74 | N5: =(M5/J9)*1 -> 0.62073475
B6: Martina Sanna | C6: 1626.67 | E6: Total Other expenses | F6: =SUM(F11:F201) -> 1700 | I6: Martina Sanna | J6: 1626.67 | L6: Total Other expenses | M6: =SUM(M11:M201) -> 1622
B7: Child Benefits | C7: =173.2 -> 173.2 | E7: "One off" big expenses | F7: 0 | I7: Child Benefits | J7: =173.2 -> 173.2 | L7: "One off" big expenses | M7: =SUM(Q23:Q25) -> 0
B8: Other's | E8: Balance | F8: =(C9-(F5+F6)) -> 1235.87 | I8: Other's | L8: Balance | M8: =(J9-(M5+M6)) -> 350.13
B9: Total monthly income | C9: =SUM(C5:C8) -> 5199.87 | I9: Total monthly income | J9: =SUM(J5:J8) -> 5199.87
B11: Monthly expenses | C11: Cost | E11: Other expenses | F11: Cost | G11: Type | I11: Monthly expenses | J11: Cost | L11: Other expenses | M11: Cost | N11: Type
A12: 1 | B12: Mortgage (36 woodlea Grove) | C12: 0 | I12: Mortgage (36 woodlea Grove) | J12: 710
A13: 1 | B13: Mortgage (New House) | C13: 2000 | E13: Groceries | F13: 600 | I13: Mortgage (New House) | J13: 1850 | L13: Groceries | M13: 600
A14: 2 | B14: Aviva (36 woodlea Grove) | C14: 0 | E14: Kids clubs + others Kids stuff | F14: 150 | I14: Aviva (36 woodlea Grove) | J14: 15.1 | L14: Kids clubs + others Kids stuff | M14: 150
A15: 2 | B15: Aviva (New House) | C15: 30 | E15: Not essentials | F15: 200 | I15: Aviva (New House) | J15: 30 | L15: Not essentials | M15: 200
A16: 3 | B16: Council Tax (36 woodlea Grove) | C16: 0 | E16: Leisure | F16: 200 | I16: Council Tax (36 woodlea Grove) | J16: 168 | L16: Leisure | M16: 200
A17: 3 | B17: Council Tax (New House) | C17: 168 | E17: Clothing | F17: 150 | I17: Council Tax (New House) | J17: 168 | L17: Clothing | M17: 150
A18: 4 | B18: Water (36 woodlea Grove) | C18: 0 | E18: agency | F18: 100 | I18: Water (36 woodlea Grove) | J18: 66 | L18: agency | M18: 100
A19: 4 | B19: Water (C) | C19: 66 | E19: Emergency 36 woodlea grove | F19: 300 | I19: Water (C) | J19: 66 | L19: Emergency 36 woodlea grove | M19: 222
A20: 5 | B20: Electricity + Gas(Bulb) © (36 woodlea Grove) | C20: 0 | I20: Electricity + Gas(Bulb) © (36 woodlea Grove) | J20: 154.64
A21: 5 | B21: Electricity + Gas(Bulb) (C) | C21: 154.64 | I21: Electricity + Gas(Bulb) (C) | J21: 154.64
A22: 6 | B22: Ageas (M) (36 woodlea Grove) | C22: 20.29 | I22: Ageas (M) (36 woodlea Grove) | J22: 20.29
A23: 6 | B23: Ageas (M) | C23: 40 | I23: Ageas (M) | J23: 40
B24: DVLA (C) | C24: 16.62 | I24: DVLA (C) | J24: 16.62
B25: Phones (three) (F) | C25: =14.5+14.5 -> 29 | I25: Phones (three) (F) | J25: =14.5+14.5 -> 29

Sheet list
A1: Select type
A2: Groceries
A3: Leisure / Days out
A4: Others (Not essential)
A5: Others (Essential)
A6: Holidays
A7: Clothing
A8: Savings
A9: Overpayment
